## 에러 처리

### try...catch...finally 문

```js
try {
// 실행할 코드(에러가 발생할 가능성이 있는 코드)
} catch (err) {
// try 코드 블록에서 에러가 발생하면 이 코드 블록의 코드가 실행된다. // err에는 try 코드 블록에서 발생한 Error 객체가 전달된다.
} finally {
// 에러 발생과 상관없이 반드시 한 번 실행된다. }
```

try...catch...finally 문을 실행하면 먼저 try 코드 블록이 실행된다.

이때 try 코드 블록에 포함된 문 중 에서 에러가 발생하면 발생한 에러는 catch 문의 err 변수에 전달되고 catch 코드 블록이 실행된다.

catch 문의 err 변수는 try 코드 블록에 포함된 문 중에서 에러가 발생하면 생성 되고 되고 catch 코드 블록에서만 유효하다.

finally 코드 블록은 에러 발생과 상관없이 반드시 한 번 실행 된다. try...catch...finally 문으로 에러를 처리하면 프로그램이 강제 종료되지 않는다.

<br />

### Error 객체

Error 생성자 함수는 에러 객체를 생성한다. Error 생성자 함수에는 에러를 상세히 설명하는 에러 메시지를 인수로 전달할 수 있다.

```js
const error = new Error("invalid");
```

Error 생성자 함수가 생성한 에러 객체는 message 프로퍼티와 stack 프로퍼티를 갖는다.

- message 프로퍼티의 값: Error 생성자 함수에 인수로 전달한 에러 메시지이다.
- stack 프로퍼티의 값: 에러를 발생시킨 콜 스택의 호출 정보를 나타내는 문자열이며 디버깅 목적으로 사용한다.

<br />
<br />

### throw 문

Error 생성자 함수로 에러 객체를 생성한다고 에러가 발생하는 것은 아니다. 즉, 에러 객체 생성과 에러 발생은 의미가 다르다.

`에러를 발생시키려면 try 코드 블록에서 throw 문으로 에러 객체를 던져야 한다.`

<br />

### 에러의 전파

`에러는 호출자 방향으로 전파된다.` 즉, 콜 스택의 아래 방향(실행 중인 실행 컨텍스트가 푸시되기 직전에 푸시된 실행 컨텍스트 방향)으로 전파된다.

throw된 에러를 캐치하지 않으면 호출자 방향으로 전파된다. 이때 throw된 에러를 캐치하여 적절히 대응하면 프로그램을 강제 종료시키지 않고 코드의 실행 흐름을 복구할 수 있다. throw된 에러를 어디에서도 캐치하지 않으면 프로그램은 강제 종료된다.
